Workbook
Name Slicer_Gender: #N/A
Name Slicer_Gender1: #N/A
Name Slicer_Payment_Type: #N/A
Name Slicer_Payment_Type1: #N/A
Name Slicer_Region: #N/A
Name Slicer_Region1: #N/A
Name Slicer_Years__Order_Date: #N/A
Name Slicer_Years__Order_Date1: #N/A

Sheet Customer_Dim
A1: Customer_ID | B1: Name | C1: Age | D1: Gender | E1: City | F1: State | G1: Country | H1: Loyalty_Level
A2: CUST1000 | B2: sheena bonilla | C2: 55 | D2: Male | E2: Donaldton | F2: North Carolina | G2: USA
A3: CUST1001 | B3: Eugene Nelson | C3: 26 | D3: Female | E3: Phillipsmouth | F3: North Dakota | G3: USA | H3: Platinum
A4: CUST1002 | B4: dr. Benjamin Price | C4: 29 | D4: Female | E4: Kylebury | F4: Alabama | G4: USA | H4: Platinum
A5: CUST1003 | B5: jeremy harris | C5: 59 | D5: Female | E5: Thomastown | F5: Ohio | G5: USA | H5: Bronze
A6: CUST1004 | B6: Caroline Collins | C6: 64 | D6: Female | E6: Nicholasshire | F6: California | G6: USA | H6: Silver
A7: CUST1005 | B7: Christine Vaughn | C7: 24 | D7: Male | E7: East Amandamouth | F7: Oregon | G7: USA | H7: Bronze
A8: CUST1006 | B8: Amber Jackson | C8: 29 | D8: Female | E8: Deborahborough | F8: South Dakota | G8: USA | H8: Platinum
A9: CUST1007 | B9: Daniel Boyd | C9: 29 | D9: Female | E9: West Pamelafurt | F9: West Virginia | G9: USA | H9: Bronze
A10: CUST1008 | B10: Melissa Howard | C10: 53 | D10: Female | E10: Maynardton | F10: New Hampshire | G10: USA | H10: Gold
A11: CUST1009 | B11: Ms. Maria Leach | C11: 64 | D11: Male | E11: Melissashire | F11: Pennsylvania | G11: USA | H11: Platinum
A12: CUST1010 | B12: Dominic Page | C12: 53 | D12: Male | E12: Port Michaelburgh | F12: Pennsylvania | G12: USA | H12: Bronze
A13: CUST1011 | B13: Brian Lopez | C13: 28 | D13: Female | E13: East Krista | F13: New York | G13: USA | H13: Gold
A14: CUST1012 | B14: Kenneth Lambert | C14: 55 | D14: Female | E14: North Kathryn | F14: Kansas | G14: USA | H14: Platinum
... A19: CUST1017 | B19: Adam Cruz | C19: 60 | D19: Female | E19: Brandonville | F19: Georgia | G19: USA | H19: Platinum
A20: CUST1018 | B20: Rhonda Moss | C20: 43 | D20: Male | E20: South William | F20: Kansas | G20: USA
A21: CUST1019 | B21: Michael Torres | C21: 46 | D21: Female | E21: Gonzalezfort | F21: New Jersey | G21: USA | H21: Platinum
A22: CUST1020 | B22: Bridget Allen | C22: 59 | D22: Male | E22: Lake Shaneburgh | F22: Delaware | G22: USA | H22: Silver
A23: CUST1021 | B23: Jeff Martinez | C23: 36 | D23: Female | E23: Smithburgh | F23: Oklahoma | G23: USA | H23: Gold
A24: CUST1022 | B24: paul fox | C24: 33 | D24: Female | E24: Michaelton | F24: Hawaii | G24: USA | H24: Silver
A25: CUST1023 | B25: Jonathan Steele | C25: 52 | D25: Female | E25: Molinabury | F25: Oregon | G25: USA | H25: Silver
A26: CUST1024 | B26: Heather Collins | C26: 40 | D26: Male | E26: Rogerschester | F26: Idaho | G26: USA | H26: Platinum
A27: CUST1025 | B27: Diana Taylor | C27: 59 | D27: Female | E27: Vasqueztown | F27: California | G27: USA | H27: Bronze
A28: CUST1026 | B28: Amber Carlson | C28: 18 | D28: Female | E28: East Michellemouth | F28: Missouri | G28: USA | H28: Gold
A29: CUST1027 | B29: Leslie Johnson | C29: 31 | D29: Male | E29: Mollyshire | F29: Utah | G29: USA
A30: CUST1028 | B30: Joshua Ryan | C30: 27 | D30: Female | E30: New David | F30: New Jersey | G30: USA | H30: Platinum
A31: CUST1029 | B31: David Arnold | C31: 54 | D31: Female | E31: East Jennifer | F31: California | G31: USA | H31: Silver
A32: CUST1030 | B32: Jessica Acevedo | C32: 64 | D32: Female | E32: Amybury | F32: Pennsylvania | G32: USA | H32: Bronze
A33: CUST1031 | B33: Sarah Vance | C33: 41 | D33: Male | E33: Johnsonville | F33: Oregon | G33: USA | H33: Silver
A34: CUST1032 | B34: Mike Jennings | C34: 48 | D34: Female | E34: Fostermouth | F34: Arizona | G34: USA | H34: Gold
A35: CUST1033 | B35: Robert Jones DDS | C35: 25 | D35: Male | E35: Tristanton | F35: Oklahoma | G35: USA | H35: Platinum
A36: CUST1034 | B36: Christopher Olson | C36: 27 | D36: Female | E36: West Richard | F36: Maryland | G36: USA | H36: Platinum
A37: CUST1035 | B37: Rachel Myers | C37: 52 | D37: Male | E37: Robertberg | F37: North Dakota | G37: USA | H37: Silver
A38: CUST1036 | B38: Thomas Phillips | C38: 20 | D38: Female | E38: Luisfurt | F38: Georgia | G38: USA | H38: Gold
A39: CUST1037 | B39: Christopher Carter | C39: 27 | D39: Female | E39: Brendastad | F39: South Dakota | G39: USA
A40: CUST1038 | B40: Deanna Simpson | C40: 35 | D40: Female | E40: Brownport | F40: North Dakota | G40: USA | H40: Bronze
A41: CUST1039 | B41: Tonya Reynolds | C41: 55 | D41: Female | E41: Darleneton | F41: Michigan | G41: USA | H41: Gold
A42: CUST1040 | B42: Eric Vega | C42: 50 | D42: Male | E42: Williamsonland | F42: Kansas | G42: USA | H42: Gold
A43: CUST1041 | B43: James Gibbs | C43: 21 | D43: Male | E43: Mooneyshire | F43: Alaska | G43: USA | H43: Platinum
A44: CUST1042 | B44: William Martin | C44: 19 | D44: Male | E44: Ryanburgh | F44: Connecticut | G44: USA | H44: Platinum
...

Sheet Product_Dim
A1: Product_ID | B1: Product_Name | C1: Category | D1: Sub_Category | E1: Brand | F1: Cost | G1: Stock
A2: PROD0 | B2: Brother Laser Printer | C2: Electronics | D2: Computer | E2: Hunt Inc | F2: 112.42 | G2: 416
A3: PROD1 | B3: Men's Graphic T-Shirt | C3: Clothing | D3: Tops | E3: Terry-Moore | F3: 342.56 | G3: 181
A4: PROD2 | B4: Women's Casual Hoodie | C4: Clothing | D4: Outerwear | E4: Sims Inc | G4: 352
A5: P-3 | B5: Men's Running Jacket | C5: Clothing | D5: Outerwear | E5: Pineda Ltd | F5: 364.67 | G5: 452
A6: PROD4 | B6: Women's Yoga Pants | C6: Clothing | D6: Bottoms | E6: Gonzales-Davis | F6: 306.46 | G6: 487
A7: PROD5 | B7: Men's Leather Belt | C7: Clothing | D7: Accessories | E7: Baldwin, Garza and Gonzalez | F7: 261 | G7: 59
A8: PROD6 | B8: Herbal Face Moisturizer | C8: Beauty | D8: Skincare | E8: Davidson PLC | F8: 312.8 | G8: 350
A9: PROD7 | B9: LED Table Lamp | C9: Home | D9: Lighting | E9: Harrell LLC | F9: 218.86 | G9: 170
A10: PROD8 | B10: Wireless Bluetooth Earbuds | C10: Electronics | D10: Audio | E10: Perez-Johnston | F10: 439.07 | G10: 142
A11: PROD9 | B11: Adjustable Dumbbell Set | C11: Sports | D11: Fitness | E11: Hill PLC | F11: 495.72 | G11: 323
A12: PROD10 | B12: Ceramic Kitchen Bowl Set | C12: Home | D12: Kitchen | E12: Hamilton Group | F12: 298.86 | G12: 308
A13: PROD11 | B13: HD Smart TV Stick | C13: Electronics | D13: Accessories | E13: Gibson, Hobbs and Weaver | F13: 449.4
A14: PROD12 | B14: Hair Strengthening Shampoo | C14: Beauty | D14: Haircare | E14: Rice LLC | F14: 115.82 | G14: 460
A15: PROD13 | B15: USB-C Fast Charger | C15: Electronics | D15: Accessories | E15: Dawson-Perkins | F15: 242.23 | G15: 453
A16: PROD14 | B16: Decorative Wall Mirror | C16: Home | D16: Decor | E16: Luna, Anderson and Bowman | F16: 48.01 | G16: 439
A17: PROD15 | B17: 4K Home Projector | C17: Electronics | D17: Appliances | E17: Thomas LLC | F17: 465.34 | G17: 301
A18: P-16 | B18: Beard Grooming Kit | C18: Beauty | D18: Grooming | E18: Erickson-Green | F18: 337.42 | G18: 256
A19: PROD17 | B19: Soccer Training Cone Set | C19: Sports | D19: Accessories | E19: Ford, Murphy and Wilson | F19: 144.53 | G19: 367
A20: PROD18 | B20: Women's Denim Jeans | C20: Clothing | D20: Bottoms | E20: Guerra-Hendrix | G20: 343
A21: PROD19 | B21: Knee Support Brace | C21: Sports | D21: Equipment | E21: May-Reese | F21: 21.34 | G21: 65
A22: PROD20 | B22: Outdoor Sports Water Bottle | C22: Sports | D22: Accessories | E22: Soto-Ellis | F22: 131.51
A23: PROD21 | B23: Multi-Purpose Storage Box | C23: Home | D23: Storage | E23: Gardner-Montes | F23: 123.46 | G23: 76
A24: PROD22 | B24: Carbon Fiber Tennis Racket | C24: Sports | D24: Equipment | E24: Flores, Pineda and Rodriguez | F24: 484.62 | G24: 432
A25: PROD23 | B25: Men's Formal Shirt | C25: Clothing | D25: Tops | E25: Moon, Mora and Santos | G25: 360
A26: PROD24 | B26: Foldable Camping Chair | C26: Sports | D26: Outdoor | E26: Cook Ltd | F26: 166.06 | G26: 340
A27: PROD25 | B27: Women's Scarf Set | C27: Clothing | D27: Accessories | E27: Brown and Sons | F27: 174.02 | G27: 268
A28: PROD26 | B28: Wireless Bluetooth Speaker | C28: Electronics | D28: Audio | E28: Reed-Schmidt | F28: 322.41 | G28: 213
A29: PROD27 | B29: Decorative Floor Vase | C29: Home | D29: Decor | E29: Khan, Jones and Paul | G29: 378
A30: PROD28 | B30: Sports Stopwatch Timer | C30: Sports | D30: Accessories | E30: Burns-Hansen | F30: 38.76 | G30: 137
A31: PROD29 | B31: Fabric Sofa Throw Blanket | C31: Home | D31: Decor | E31: Hoffman Group | F31: 218.48 | G31: 276
A32: PROD30 | B32: Stainless Steel Cutlery Set | C32: Home | D32: Kitchen | E32: Stevens, Fernandez and Martin | F32: 19.52 | G32: 57
A33: PROD31 | B33: Basketball | C33: Sports | D33: Team Sports | E33: Nolan-Snow | F33: 204.39 | G33: 281
A34: PROD32 | B34: Vitamin C Face Serum | C34: Beauty | D34: Skincare | E34: Griffin Ltd | F34: 283.83 | G34: 244
A35: PROD33 | B35: Modern Wall Clock | C35: Home | D35: Decor | E35: Weiss-Watson | F35: 179.77 | G35: 305
A36: PROD34 | B36: Gaming Mechanical Keyboard | C36: Electronics | D36: Computer | E36: Lucero LLC | F36: 419.28 | G36: 86
A37: PROD35 | B37: Bedroom Table Lamp | C37: Home | D37: Lighting | E37: Jones LLC | F37: 382.22 | G37: 329
A38: PROD36 | B38: Women's Summer Dress | C38: Clothing | D38: Tops | E38: Smith-Mills | F38: 223.43 | G38: 154
A39: PROD37 | B39: Men's Casual Sneakers | C39: Clothing | D39: Footwear | E39: Hogan-Lee | F39: 353.47 | G39: 214
A40: PROD38 | B40: Sports Water Hydration Pack | C40: Sports | D40: Outdoor | E40: Sims-Smith | F40: 135.61 | G40: 394
...

Sheet Store_Dim
A1: Store_ID | B1: Store_Name | C1: Region | D1: City | E1: Store_Type
A2: STORE0 | B2: Rivera-Warner | C2: East | D2: Washingtonfurt | E2: Flagship
A3: STORE1 | B3: Martinez, Adkins and Johnson | C3: North | D3: Danielmouth | E3: Flagship
A4: STORE2 | B4: Black-Horn | C4: South | D4: North Nancyview | E4: Outlet
A5: STORE3 | B5: Johnson-Wright | C5: North | D5: Hoodberg | E5: Outlet
A6: STORE4 | B6: Alexander Group | C6: South | D6: Port Sharon | E6: Online
A7: STORE5 | B7: Gray Ltd | C7: North | D7: New Michaelchester | E7: Outlet
A8: STORE6 | B8: Benson-Elliott | C8: East | D8: Port Josephberg | E8: Online
A9: STORE7 | B9: Martinez-Mullins | C9: South | D9: Williamsfurt | E9: Online
A10: STORE8 | B10: Bean, Jones and Park | C10: West | D10: Thompsonborough | E10: Online
A11: STORE9 | B11: Moore, Padilla and Butler | C11: South | D11: East Johnstad | E11: Flagship
A12: STORE10 | B12: Hill, Wagner and Ballard | C12: East | D12: East Davidville | E12: Online
... A21: STORE19 | B21: Mann-Austin | C21: East | D21: Vasquezborough | E21: Online

Sheet Sales_Fact
A1: Sales_ID | B1: Order_Date | C1: Customer_ID | D1: Product_ID | E1: Store_ID | F1: Quantity | G1: Unit_Price | H1: Discount | I1: Payment_Type | J1: Total_Amount
A2: SALE0 | B2: 45480 | C2: CUST1409 | D2: PROD97 | E2: STORE3 | F2: 1 | G2: 218.04 | H2: 0.09 | I2: Credit Card | J2: 198.4164
A3: SALE1 | B3: 45285 | C3: CUST1467 | D3: PROD74 | E3: STORE17 | F3: 3 | G3: 104.47 | H3: 0.27 | I3: PayPal | J3: 228.7893
A4: SALE2 | B4: 45446 | C4: CUST1056 | D4: PROD49 | E4: STORE8 | F4: 4 | G4: 914.05 | H4: 0.25 | I4: Credit Card | J4: 2742.15
A5: SALE3 | B5: 45259 | C5: CUST1346 | D5: PROD76 | E5: STORE8 | F5: 1 | G5: 921.51 | H5: 0.16 | I5: COD | J5: 774.0684
A6: SALE4 | B6: 45297 | C6: CUST1493 | D6: PROD59 | E6: STORE5 | F6: 3 | G6: 745.3 | H6: 0.18 | I6: Credit Card | J6: 1833.438
A7: SALE5 | B7: 45499 | C7: CUST1116 | D7: PROD15 | E7: STORE7 | F7: 3 | G7: 147.01 | H7: 0.19 | I7: COD | J7: 357.2343
A8: SALE6 | B8: 45850 | C8: CUST1016 | D8: PROD56 | E8: STORE4 | F8: 2 | G8: 785.31 | H8: 0.15 | I8: PayPal | J8: 1335.027
A9: SALE7 | B9: 45248 | C9: CUST1152 | D9: PROD70 | E9: STORE8 | F9: 4 | G9: 342.39 | H9: 0.23 | I9: PayPal | J9: 1054.5612
A10: SALE8 | B10: 45781 | C10: CUST1187 | D10: PROD99 | E10: STORE5 | G10: 448.25 | H10: 0.07 | I10: PayPal | J10: 1250.6175
A11: SALE9 | B11: 45869 | C11: CUST1464 | D11: PROD33 | E11: STORE0 | F11: 2 | G11: 873.17 | H11: 0.23 | I11: PayPal | J11: 1344.6818
A12: SALE10 | B12: 45335 | C12: CUST1065 | D12: PROD24 | E12: STORE14 | F12: 1 | G12: 278.63 | H12: 0.07 | I12: Credit Card | J12: 259.1259
A13: SALE11 | B13: 45801 | C13: CUST1320 | D13: PROD39 | E13: STORE1 | F13: 4 | G13: 286.92 | H13: 0.17 | I13: Credit Card | J13: 952.5744
A14: SALE12 | B14: 45528 | C14: CUST1237 | D14: PROD88 | E14: STORE4 | F14: 4 | G14: 644.58 | H14: 0.01 | I14: Credit Card | J14: 2552.5368
A15: SALE13 | B15: 45875 | C15: CUST1443 | D15: PROD34 | E15: STORE16 | F15: 2 | G15: 316.9 | H15: 0.3 | I15: PayPal | J15: 443.66
A16: SALE14 | B16: 45829 | C16: CUST1348 | D16: PROD24 | E16: STORE15 | F16: 4 | G16: 403.47 | H16: 0.29 | I16: PayPal | J16: 1145.8548
A17: SALE15 | B17: 45636 | C17: CUST1435 | D17: PROD36 | E17: STORE9 | G17: 871.34 | H17: 0.04 | I17: COD | J17: 2509.4592
A18: SALE16 | B18: 45913 | C18: CUST1276 | D18: PROD65 | E18: STORE19 | F18: 2 | G18: 451.98 | H18: 0.25 | I18: Credit Card | J18: 677.97
A19: SALE17 | B19: 45637 | C19: CUST1079 | D19: PROD27 | E19: STORE4 | F19: 2 | G19: 502.69 | H19: 0.23 | I19: Credit Card | J19: 774.1426
A20: SALE18 | B20: 45517 | C20: CUST1094 | D20: PROD39 | E20: STORE4 | F20: 2 | G20: 559.23 | H20: 0.25 | I20: COD | J20: 838.845
A21: SALE19 | B21: 45369 | C21: CUST1239 | D21: PROD60 | E21: STORE13 | F21: 4 | H21: 0.04 | I21: COD | J21: 1782.4512
A22: SALE20 | B22: 45843 | C22: CUST1144 | D22: PROD72 | E22: STORE17 | F22: 3 | G22: 986.04 | H22: 0.27 | I22: COD | J22: 2159.4276
A23: SALE21 | B23: 45447 | C23: CUST1396 | D23: PROD43 | E23: STORE18 | F23: 1 | G23: 589.56 | H23: 0.22 | I23: Credit Card | J23: 459.8568
A24: SALE22 | B24: 45394 | C24: CUST1476 | D24: PROD69 | E24: STORE10 | F24: 3 | G24: 979.42 | H24: 0.03 | I24: PayPal | J24: 2850.1122
A25: SALE23 | B25: 45466 | C25: CUST1368 | D25: PROD12 | E25: STORE8 | F25: 1 | G25: 719.28 | H25: 0.08 | I25: Credit Card | J25: 661.7376
A26: SALE24 | B26: 45908 | C26: CUST1186 | D26: PROD67 | E26: STORE6 | F26: 3 | G26: 77.6 | H26: 0.07 | I26: Credit Card | J26: 216.504
A27: SALE25 | B27: 45552 | C27: CUST1381 | D27: PROD5 | E27: STORE3 | F27: 4 | G27: 852.71 | H27: 0.14 | I27: PayPal | J27: 2933.3224
A28: SALE26 | B28: 45294 | C28: CUST1213 | D28: PROD98 | E28: STORE8 | F28: 4 | G28: 156.16 | I28: Credit Card | J28: 599.6544
A29: SALE27 | B29: 45710 | C29: CUST1200 | D29: PROD77 | E29: STORE8 | F29: 3 | G29: 815.49 | H29: 0.17 | I29: Credit Card | J29: 2030.5701
A30: SALE28 | B30: 45923 | C30: CUST1148 | D30: PROD13 | E30: STORE2 | F30: 2 | G30: 74.21 | H30: 0.11 | I30: PayPal | J30: 132.0938
A31: SALE29 | B31: 45302 | C31: CUST1348 | D31: PROD99 | E31: STORE3 | G31: 451.67 | H31: 0.15 | I31: Credit Card | J31: 1535.678
A32: SALE30 | B32: 45217 | C32: CUST1028 | D32: PROD5 | E32: STORE19 | F32: 1 | G32: 429.38 | H32: 0.13 | I32: PayPal | J32: 373.5606
A33: SALE31 | B33: 45593 | C33: CUST1412 | D33: PROD53 | E33: STORE12 | F33: 2 | G33: 148.96 | H33: 0.03 | I33: COD | J33: 288.9824
A34: SALE32 | B34: 45597 | C34: CUST1398 | D34: PROD75 | E34: STORE8 | F34: 4 | G34: 313.83 | H34: 0.08 | I34: Credit Card | J34: 1154.8944
A35: SALE33 | B35: 45620 | C35: CUST1453 | D35: PROD12 | E35: STORE6 | F35: 2 | G35: 717.31 | H35: 0.15 | I35: Credit Card | J35: 1219.427
A36: SALE34 | B36: 45215 | C36: CUST1344 | D36: PROD79 | E36: STORE1 | G36: 873.22 | H36: 0.18 | I36: Credit Card | J36: 2148.1212
A37: SALE35 | B37: 45878 | C37: CUST1218 | D37: PROD16 | E37: STORE3 | F37: 4 | G37: 109.36 | H37: 0.19 | I37: COD | J37: 354.3264
A38: SALE36 | B38: 45635 | C38: CUST1086 | D38: PROD5 | E38: STORE7 | F38: 3 | G38: 559.52 | H38: 0.16 | I38: PayPal | J38: 1409.9904
A39: SALE37 | B39: 45329 | C39: CUST1492 | D39: PROD10 | E39: STORE17 | F39: 3 | G39: 121.76 | H39: 0.27 | I39: PayPal | J39: 266.6544
A40: SALE38 | B40: 45378 | C40: CUST1189 | D40: PROD33 | E40: STORE13 | F40: 4 | G40: 735.32 | H40: 0.06 | I40: COD | J40: 2764.8032
...

Sheet Customer_Dim_Clean
A1: Customer_ID | B1: Name | C1: Age | D1: Gender | E1: City | F1: State | G1: Country | H1: Loyalty_Level
A2: CUST1000 | B2: =TRIM(Customer_Dim!B2) -> sheena bonilla | C2: 55 | D2: Male | E2: Donaldton | F2: North Carolina | G2: USA | H2: Unknown
A3: CUST1001 | B3: =TRIM(Customer_Dim!B3) -> Eugene Nelson | C3: 26 | D3: Female | E3: Phillipsmouth | F3: North Dakota | G3: USA | H3: Platinum
A4: CUST1002 | B4: =TRIM(Customer_Dim!B4) -> dr. Benjamin Price | C4: 29 | D4: Female | E4: Kylebury | F4: Alabama | G4: USA | H4: Platinum
A5: CUST1003 | B5: =TRIM(Customer_Dim!B5) -> jeremy harris | C5: 59 | D5: Female | E5: Thomastown | F5: Ohio | G5: USA | H5: Bronze
A6: CUST1004 | B6: =TRIM(Customer_Dim!B6) -> Caroline Collins | C6: 64 | D6: Female | E6: Nicholasshire | F6: California | G6: USA | H6: Silver
A7: CUST1005 | B7: =TRIM(Customer_Dim!B7) -> Christine Vaughn | C7: 24 | D7: Male | E7: East Amandamouth | F7: Oregon | G7: USA | H7: Bronze
A8: CUST1006 | B8: =TRIM(Customer_Dim!B8) -> Amber Jackson | C8: 29 | D8: Female | E8: Deborahborough | F8: South Dakota | G8: USA | H8: Platinum
A9: CUST1007 | B9: =TRIM(Customer_Dim!B9) -> Daniel Boyd | C9: 29 | D9: Female | E9: West Pamelafurt | F9: West Virginia | G9: USA | H9: Bronze
A10: CUST1008 | B10: =TRIM(Customer_Dim!B10) -> Melissa Howard | C10: 53 | D10: Female | E10: Maynardton | F10: New Hampshire | G10: USA | H10: Gold
A11: CUST1009 | B11: =TRIM(Customer_Dim!B11) -> Ms. Maria Leach | C11: 64 | D11: Male | E11: Melissashire | F11: Pennsylvania | G11: USA | H11: Platinum
A12: CUST1010 | B12: =TRIM(Customer_Dim!B12) -> Dominic Page | C12: 53 | D12: Male | E12: Port Michaelburgh | F12: Pennsylvania | G12: USA | H12: Bronze
A13: CUST1011 | B13: =TRIM(Customer_Dim!B13) -> Brian Lopez | C13: 28 | D13: Female | E13: East Krista | F13: New York | G13: USA | H13: Gold
... A501: CUST 1499 | B501: =TRIM(Customer_Dim!B501) -> Philip Pennington | C501: 27 | D501: Female | E501: East Valerieview | F501: Oregon | G501: USA | H501: Platinum

Sheet Product_Dim _Clean
A1: Product_ID | B1: Product_Name | C1: Category | D1: Sub_Category | E1: Brand | F1: Cost | G1: Stock | H1: crt_Stock
A2: PROD0 | B2: Brother Laser Printer | C2: Electronics | D2: Computer | E2: Hunt Inc | F2: =IF(Product_Dim!D2="",MEDIAN(Product_Dim!D1:D101),ProductTbl[[#This Row],[Cost]]) -> 112.42 | G2: 416 | H2: =IF(G2="",MEDIAN(ProductTbl[Stock]),ProductTbl[[#This Row],[Stock]]) -> 416
A3: PROD1 | B3: Men's Graphic T-Shirt | C3: Clothing | D3: Tops | E3: Terry-Moore | F3: =IF(Product_Dim!D3="",MEDIAN(Product_Dim!D2:D102),ProductTbl[[#This Row],[Cost]]) -> 342.56 | G3: 181 | H3: =IF(G3="",MEDIAN(ProductTbl[Stock]),ProductTbl[[#This Row],[Stock]]) -> 181
A4: PROD2 | B4: Women's Casual Hoodie | C4: Clothing | D4: Outerwear | E4: Sims Inc | F4: =IF(Product_Dim!D4="",MEDIAN(Product_Dim!D3:D103),ProductTbl[[#This Row],[Cost]]) -> 243.7 | G4: 352 | H4: =IF(G4="",MEDIAN(ProductTbl[Stock]),ProductTbl[[#This Row],[Stock]]) -> 352
A5: PROD3 | B5: Men's Running Jacket | C5: Clothing | D5: Outerwear | E5: Pineda Ltd | F5: =IF(Product_Dim!D5="",MEDIAN(Product_Dim!D4:D104),ProductTbl[[#This Row],[Cost]]) -> 364.67 | G5: 452 | H5: =IF(G5="",MEDIAN(ProductTbl[Stock]),ProductTbl[[#This Row],[Stock]]) -> 452
A6: PROD4 | B6: Women's Yoga Pants | C6: Clothing | D6: Bottoms | E6: Gonzales-Davis | F6: =IF(Product_Dim!D6="",MEDIAN(Product_Dim!D5:D105),ProductTbl[[#This Row],[Cost]]) -> 306.46 | G6: 487 | H6: =IF(G6="",MEDIAN(ProductTbl[Stock]),ProductTbl[[#This Row],[Stock]]) -> 487
A7: PROD5 | B7: Men's Leather Belt | C7: Clothing | D7: Accessories | E7: Baldwin, Garza and Gonzalez | F7: =IF(Product_Dim!D7="",MEDIAN(Product_Dim!D6:D106),ProductTbl[[#This Row],[Cost]]) -> 261 | G7: 59 | H7: =IF(G7="",MEDIAN(ProductTbl[Stock]),ProductTbl[[#This Row],[Stock]]) -> 59
A8: PROD6 | B8: Herbal Face Moisturizer | C8: Beauty | D8: Skincare | E8: Davidson PLC | F8: =IF(Product_Dim!D8="",MEDIAN(Product_Dim!D7:D107),ProductTbl[[#This Row],[Cost]]) -> 312.8 | G8: 350 | H8: =IF(G8="",MEDIAN(ProductTbl[Stock]),ProductTbl[[#This Row],[Stock]]) -> 350
A9: PROD7 | B9: LED Table Lamp | C9: Home | D9: Lighting | E9: Harrell LLC | F9: =IF(Product_Dim!D9="",MEDIAN(Product_Dim!D8:D108),ProductTbl[[#This Row],[Cost]]) -> 218.86 | G9: 170 | H9: =IF(G9="",MEDIAN(ProductTbl[Stock]),ProductTbl[[#This Row],[Stock]]) -> 170
A10: PROD8 | B10: Wireless Bluetooth Earbuds | C10: Electronics | D10: Audio | E10: Perez-Johnston | F10: =IF(Product_Dim!D10="",MEDIAN(Product_Dim!D9:D109),ProductTbl[[#This Row],[Cost]]) -> 439.07 | G10: 142 | H10: =IF(G10="",MEDIAN(ProductTbl[Stock]),ProductTbl[[#This Row],[Stock]]) -> 142
A11: PROD9 | B11: Adjustable Dumbbell Set | C11: Sports | D11: Fitness | E11: Hill PLC | F11: =IF(Product_Dim!D11="",MEDIAN(Product_Dim!D10:D110),ProductTbl[[#This Row],[Cost]]) -> 495.72 | G11: 323 | H11: =IF(G11="",MEDIAN(ProductTbl[Stock]),ProductTbl[[#This Row],[Stock]]) -> 323
A12: PROD10 | B12: Ceramic Kitchen Bowl Set | C12: Home | D12: Kitchen | E12: Hamilton Group | F12: =IF(Product_Dim!D12="",MEDIAN(Product_Dim!D11:D111),ProductTbl[[#This Row],[Cost]]) -> 298.86 | G12: 308 | H12: =IF(G12="",MEDIAN(ProductTbl[Stock]),ProductTbl[[#This Row],[Stock]]) -> 308
A13: PROD11 | B13: HD Smart TV Stick | C13: Electronics | D13: Accessories | E13: Gibson, Hobbs and Weaver | F13: =IF(Product_Dim!D13="",MEDIAN(Product_Dim!D12:D112),ProductTbl[[#This Row],[Cost]]) -> 449.4 | H13: =IF(G13="",MEDIAN(ProductTbl[Stock]),ProductTbl[[#This Row],[Stock]]) -> 276
A14: PROD12 | B14: Hair Strengthening Shampoo | C14: Beauty | D14: Haircare | E14: Rice LLC | F14: =IF(Product_Dim!D14="",MEDIAN(Product_Dim!D13:D113),ProductTbl[[#This Row],[Cost]]) -> 115.82 | G14: 460 | H14: =IF(G14="",MEDIAN(ProductTbl[Stock]),ProductTbl[[#This Row],[Stock]]) -> 460
A15: PROD13 | B15: USB-C Fast Charger | C15: Electronics | D15: Accessories | E15: Dawson-Perkins | F15: =IF(Product_Dim!D15="",MEDIAN(Product_Dim!D14:D114),ProductTbl[[#This Row],[Cost]]) -> 242.23 | G15: 453 | H15: =IF(G15="",MEDIAN(ProductTbl[Stock]),ProductTbl[[#This Row],[Stock]]) -> 453
A16: PROD14 | B16: Decorative Wall Mirror | C16: Home | D16: Decor | E16: Luna, Anderson and Bowman | F16: =IF(Product_Dim!D16="",MEDIAN(Product_Dim!D15:D115),ProductTbl[[#This Row],[Cost]]) -> 48.01 | G16: 439 | H16: =IF(G16="",MEDIAN(ProductTbl[Stock]),ProductTbl[[#This Row],[Stock]]) -> 439
A17: PROD15 | B17: 4K Home Projector | C17: Electronics | D17: Appliances | E17: Thomas LLC | F17: =IF(Product_Dim!D17="",MEDIAN(Product_Dim!D16:D116),ProductTbl[[#This Row],[Cost]]) -> 465.34 | G17: 301 | H17: =IF(G17="",MEDIAN(ProductTbl[Stock]),ProductTbl[[#This Row],[Stock]]) -> 301
A18: PROD16 | B18: Beard Grooming Kit | C18: Beauty | D18: Grooming | E18: Erickson-Green | F18: =IF(Product_Dim!D18="",MEDIAN(Product_Dim!D17:D117),ProductTbl[[#This Row],[Cost]]) -> 337.42 | G18: 256 | H18: =IF(G18="",MEDIAN(ProductTbl[Stock]),ProductTbl[[#This Row],[Stock]]) -> 256
A19: PROD17 | B19: Soccer Training Cone Set | C19: Sports | D19: Accessories | E19: Ford, Murphy and Wilson | F19: =IF(Product_Dim!D19="",MEDIAN(Product_Dim!D18:D118),ProductTbl[[#This Row],[Cost]]) -> 144.53 | G19: 367 | H19: =IF(G19="",MEDIAN(ProductTbl[Stock]),ProductTbl[[#This Row],[Stock]]) -> 367
A20: PROD18 | B20: Women's Denim Jeans | C20: Clothing | D20: Bottoms | E20: Guerra-Hendrix | F20: =IF(Product_Dim!D20="",MEDIAN(Product_Dim!D19:D119),ProductTbl[[#This Row],[Cost]]) -> 220.955 | G20: 343 | H20: =IF(G20="",MEDIAN(ProductTbl[Stock]),ProductTbl[[#This Row],[Stock]]) -> 343
A21: PROD19 | B21: Knee Support Brace | C21: Sports | D21: Equipment | E21: May-Reese | F21: =IF(Product_Dim!D21="",MEDIAN(Product_Dim!D20:D120),ProductTbl[[#This Row],[Cost]]) -> 21.34 | G21: 65 | H21: =IF(G21="",MEDIAN(ProductTbl[Stock]),ProductTbl[[#This Row],[Stock]]) -> 65
A22: PROD20 | B22: Outdoor Sports Water Bottle | C22: Sports | D22: Accessories | E22: Soto-Ellis | F22: =IF(Product_Dim!D22="",MEDIAN(Product_Dim!D21:D121),ProductTbl[[#This Row],[Cost]]) -> 131.51 | H22: =IF(G22="",MEDIAN(ProductTbl[Stock]),ProductTbl[[#This Row],[Stock]]) -> 276
A23: PROD21 | B23: Multi-Purpose Storage Box | C23: Home | D23: Storage | E23: Gardner-Montes | F23: =IF(Product_Dim!D23="",MEDIAN(Product_Dim!D22:D122),ProductTbl[[#This Row],[Cost]]) -> 123.46 | G23: 76 | H23: =IF(G23="",MEDIAN(ProductTbl[Stock]),ProductTbl[[#This Row],[Stock]]) -> 76
A24: PROD22 | B24: Carbon Fiber Tennis Racket | C24: Sports | D24: Equipment | E24: Flores, Pineda and Rodriguez | F24: =IF(Product_Dim!D24="",MEDIAN(Product_Dim!D23:D123),ProductTbl[[#This Row],[Cost]]) -> 484.62 | G24: 432 | H24: =IF(G24="",MEDIAN(ProductTbl[Stock]),ProductTbl[[#This Row],[Stock]]) -> 432
A25: PROD23 | B25: Men's Formal Shirt | C25: Clothing | D25: Tops | E25: Moon, Mora and Santos | F25: =IF(Product_Dim!D25="",MEDIAN(Product_Dim!D24:D124),ProductTbl[[#This Row],[Cost]]) -> 234.58 | G25: 360 | H25: =IF(G25="",MEDIAN(ProductTbl[Stock]),ProductTbl[[#This Row],[Stock]]) -> 360
A26: PROD24 | B26: Foldable Camping Chair | C26: Sports | D26: Outdoor | E26: Cook Ltd | F26: =IF(Product_Dim!D26="",MEDIAN(Product_Dim!D25:D125),ProductTbl[[#This Row],[Cost]]) -> 166.06 | G26: 340 | H26: =IF(G26="",MEDIAN(ProductTbl[Stock]),ProductTbl[[#This Row],[Stock]]) -> 340
A27: PROD25 | B27: Women's Scarf Set | C27: Clothing | D27: Accessories | E27: Brown and Sons | F27: =IF(Product_Dim!D27="",MEDIAN(Product_Dim!D26:D126),ProductTbl[[#This Row],[Cost]]) -> 174.02 | G27: 268 | H27: =IF(G27="",MEDIAN(ProductTbl[Stock]),ProductTbl[[#This Row],[Stock]]) -> 268
A28: PROD26 | B28: Wireless Bluetooth Speaker | C28: Electronics | D28: Audio | E28: Reed-Schmidt | F28: =IF(Product_Dim!D28="",MEDIAN(Product_Dim!D27:D127),ProductTbl[[#This Row],[Cost]]) -> 322.41 | G28: 213 | H28: =IF(G28="",MEDIAN(ProductTbl[Stock]),ProductTbl[[#This Row],[Stock]]) -> 213
A29: PROD27 | B29: Decorative Floor Vase | C29: Home | D29: Decor | E29: Khan, Jones and Paul | F29: =IF(Product_Dim!D29="",MEDIAN(Product_Dim!D28:D128),ProductTbl[[#This Row],[Cost]]) -> 240.63 | G29: 378 | H29: =IF(G29="",MEDIAN(ProductTbl[Stock]),ProductTbl[[#This Row],[Stock]]) -> 378
A30: PROD28 | B30: Sports Stopwatch Timer | C30: Sports | D30: Accessories | E30: Burns-Hansen | F30: =IF(Product_Dim!D30="",MEDIAN(Product_Dim!D29:D129),ProductTbl[[#This Row],[Cost]]) -> 38.76 | G30: 137 | H30: =IF(G30="",MEDIAN(ProductTbl[Stock]),ProductTbl[[#This Row],[Stock]]) -> 137
A31: PROD29 | B31: Fabric Sofa Throw Blanket | C31: Home | D31: Decor | E31: Hoffman Group | F31: =IF(Product_Dim!D31="",MEDIAN(Product_Dim!D30:D130),ProductTbl[[#This Row],[Cost]]) -> 218.48 | G31: 276 | H31: =IF(G31="",MEDIAN(ProductTbl[Stock]),ProductTbl[[#This Row],[Stock]]) -> 276
A32: PROD30 | B32: Stainless Steel Cutlery Set | C32: Home | D32: Kitchen | E32: Stevens, Fernandez and Martin | F32: =IF(Product_Dim!D32="",MEDIAN(Product_Dim!D31:D131),ProductTbl[[#This Row],[Cost]]) -> 19.52 | G32: 57 | H32: =IF(G32="",MEDIAN(ProductTbl[Stock]),ProductTbl[[#This Row],[Stock]]) -> 57
A33: PROD31 | B33: Basketball | C33: Sports | D33: Team Sports | E33: Nolan-Snow | F33: =IF(Product_Dim!D33="",MEDIAN(Product_Dim!D32:D132),ProductTbl[[#This Row],[Cost]]) -> 204.39 | G33: 281 | H33: =IF(G33="",MEDIAN(ProductTbl[Stock]),ProductTbl[[#This Row],[Stock]]) -> 281
A34: PROD32 | B34: Vitamin C Face Serum | C34: Beauty | D34: Skincare | E34: Griffin Ltd | F34: =IF(Product_Dim!D34="",MEDIAN(Product_Dim!D33:D133),ProductTbl[[#This Row],[Cost]]) -> 283.83 | G34: 244 | H34: =IF(G34="",MEDIAN(ProductTbl[Stock]),ProductTbl[[#This Row],[Stock]]) -> 244
... A56: PROD54 | B56: Sports Stopwatch Pro | C56: Sports | D56: Accessories | E56: Thompson-French | F56: =IF(Product_Dim!D56="",MEDIAN(Product_Dim!D55:D155),ProductTbl[[#This Row],[Cost]]) -> 434.84 | G56: 185 | H56: =IF(G56="",MEDIAN(ProductTbl[Stock]),ProductTbl[[#This Row],[Stock]]) -> 185
A57: PROD55 | B57: Ceramic Plant Pot | C57: Home | D57: Decor | E57: Hatfield, Baird and Torres | F57: =IF(Product_Dim!D57="",MEDIAN(Product_Dim!D56:D156),ProductTbl[[#This Row],[Cost]]) -> 81.75 | H57: =IF(G57="",MEDIAN(ProductTbl[Stock]),ProductTbl[[#This Row],[Stock]]) -> 276
A58: PROD56 | B58: Premium Blanket Throw | C58: Home | D58: Decor | E58: Hernandez, Kennedy and Porter | F58: =IF(Product_Dim!D58="",MEDIAN(Product_Dim!D57:D157),ProductTbl[[#This Row],[Cost]]) -> 461.47 | G58: 190 | H58: =IF(G58="",MEDIAN(ProductTbl[Stock]),ProductTbl[[#This Row],[Stock]]) -> 190
A59: PROD57 | B59: Foam Roller | C59: Sports | D59: Fitness | E59: Atkinson, Camacho and Oliver | F59: =IF(Product_Dim!D59="",MEDIAN(Product_Dim!D58:D158),ProductTbl[[#This Row],[Cost]]) -> 30.62 | G59: 138 | H59: =IF(G59="",MEDIAN(ProductTbl[Stock]),ProductTbl[[#This Row],[Stock]]) -> 138
A60: PROD58 | B60: Womens Cotton Scarf | C60: Clothing | D60: Accessories | E60: Shepherd-Gould | F60: =IF(Product_Dim!D60="",MEDIAN(Product_Dim!D59:D159),ProductTbl[[#This Row],[Cost]]) -> 113.83 | G60: 485 | H60: =IF(G60="",MEDIAN(ProductTbl[Stock]),ProductTbl[[#This Row],[Stock]]) -> 485
A61: PROD59 | B61: Men's Hair Styling Gel | C61: Beauty | D61: Haircare | E61: Cline-Mccarthy | F61: =IF(Product_Dim!D61="",MEDIAN(Product_Dim!D60:D160),ProductTbl[[#This Row],[Cost]]) -> 17.31 | G61: 399 | H61: =IF(G61="",MEDIAN(ProductTbl[Stock]),ProductTbl[[#This Row],[Stock]]) -> 399
...

Sheet Store_Dim_Clean
A1: Store_ID | B1: Store_Name | C1: Region | D1: City | E1: Store_Type
A2: STORE0 | B2: Rivera-Warner | C2: East | D2: Washingtonfurt | E2: Flagship
A3: STORE1 | B3: Martinez, Adkins and Johnson | C3: North | D3: Danielmouth | E3: Flagship
A4: STORE2 | B4: Black-Horn | C4: South | D4: North Nancyview | E4: Outlet
A5: STORE3 | B5: Johnson-Wright | C5: North | D5: Hoodberg | E5: Outlet
A6: STORE4 | B6: Alexander Group | C6: South | D6: Port Sharon | E6: Online
A7: STORE5 | B7: Gray Ltd | C7: North | D7: New Michaelchester | E7: Outlet
A8: STORE6 | B8: Benson-Elliott | C8: East | D8: Port Josephberg | E8: Online
A9: STORE7 | B9: Martinez-Mullins | C9: South | D9: Williamsfurt | E9: Online
A10: STORE8 | B10: Bean, Jones and Park | C10: West | D10: Thompsonborough | E10: Online
A11: STORE9 | B11: Moore, Padilla and Butler | C11: South | D11: East Johnstad | E11: Flagship
A12: STORE10 | B12: Hill, Wagner and Ballard | C12: East | D12: East Davidville | E12: Online
... A21: STORE19 | B21: Mann-Austin | C21: East | D21: Vasquezborough | E21: Online

Sheet Sales_Fact_Clean
A1: Sales_ID | B1: Order_Date | C1: Customer_ID | D1: Product_ID | E1: Store_ID | F1: Quantity | G1: Unit_Price | H1: Discount | I1: Payment_Type | J1: Total_Amount | K1: crt_Total_Amount | L1: crt_Discount | M1: crt_Unit_Price | N1: Crt_Quantity
A2: SALE0 | B2: 45480 | C2: CUST1409 | D2: PROD97 | E2: STORE3 | F2: 1 | G2: 218.04 | H2: 0.09 | I2: Credit Card | J2: 198.4164 | K2: =IF(J2="",MEDIAN(SalesTbl[Total_Amount]),J2) -> 198.4164 | L2: =IF(H2="",MEDIAN(SalesTbl[Discount]),H2) -> 0.09 | M2: =IF(G2="",MEDIAN(SalesTbl[Unit_Price]),G2) -> 218.04 | N2: =IF(F2="",MEDIAN(SalesTbl[Quantity]),F2) -> 1
A3: SALE1 | B3: 45285 | C3: CUST1467 | D3: PROD74 | E3: STORE17 | F3: 3 | G3: 104.47 | H3: 0.27 | I3: PayPal | J3: 228.7893 | K3: =IF(J3="",MEDIAN(SalesTbl[Total_Amount]),J3) -> 228.7893 | L3: =IF(H3="",MEDIAN(SalesTbl[Discount]),H3) -> 0.27 | M3: =IF(G3="",MEDIAN(SalesTbl[Unit_Price]),G3) -> 104.47 | N3: =IF(F3="",MEDIAN(SalesTbl[Quantity]),F3) -> 3
A4: SALE2 | B4: 45446 | C4: CUST1056 | D4: PROD49 | E4: STORE8 | F4: 4 | G4: 914.05 | H4: 0.25 | I4: Credit Card | J4: 2742.15 | K4: =IF(J4="",MEDIAN(SalesTbl[Total_Amount]),J4) -> 2742.15 | L4: =IF(H4="",MEDIAN(SalesTbl[Discount]),H4) -> 0.25 | M4: =IF(G4="",MEDIAN(SalesTbl[Unit_Price]),G4) -> 914.05 | N4: =IF(F4="",MEDIAN(SalesTbl[Quantity]),F4) -> 4
A5: SALE3 | B5: 45259 | C5: CUST1346 | D5: PROD76 | E5: STORE8 | F5: 1 | G5: 921.51 | H5: 0.16 | I5: COD | J5: 774.0684 | K5: =IF(J5="",MEDIAN(SalesTbl[Total_Amount]),J5) -> 774.0684 | L5: =IF(H5="",MEDIAN(SalesTbl[Discount]),H5) -> 0.16 | M5: =IF(G5="",MEDIAN(SalesTbl[Unit_Price]),G5) -> 921.51 | N5: =IF(F5="",MEDIAN(SalesTbl[Quantity]),F5) -> 1
A6: SALE4 | B6: 45297 | C6: CUST1493 | D6: PROD59 | E6: STORE5 | F6: 3 | G6: 745.3 | H6: 0.18 | I6: Credit Card | J6: 1833.438 | K6: =IF(J6="",MEDIAN(SalesTbl[Total_Amount]),J6) -> 1833.438 | L6: =IF(H6="",MEDIAN(SalesTbl[Discount]),H6) -> 0.18 | M6: =IF(G6="",MEDIAN(SalesTbl[Unit_Price]),G6) -> 745.3 | N6: =IF(F6="",MEDIAN(SalesTbl[Quantity]),F6) -> 3
A7: SALE5 | B7: 45499 | C7: CUST1116 | D7: PROD15 | E7: STORE7 | F7: 3 | G7: 147.01 | H7: 0.19 | I7: COD | J7: 357.2343 | K7: =IF(J7="",MEDIAN(SalesTbl[Total_Amount]),J7) -> 357.2343 | L7: =IF(H7="",MEDIAN(SalesTbl[Discount]),H7) -> 0.19 | M7: =IF(G7="",MEDIAN(SalesTbl[Unit_Price]),G7) -> 147.01 | N7: =IF(F7="",MEDIAN(SalesTbl[Quantity]),F7) -> 3
A8: SALE6 | B8: 45850 | C8: CUST1016 | D8: PROD56 | E8: STORE4 | F8: 2 | G8: 785.31 | H8: 0.15 | I8: PayPal | J8: 1335.027 | K8: =IF(J8="",MEDIAN(SalesTbl[Total_Amount]),J8) -> 1335.027 | L8: =IF(H8="",MEDIAN(SalesTbl[Discount]),H8) -> 0.15 | M8: =IF(G8="",MEDIAN(SalesTbl[Unit_Price]),G8) -> 785.31 | N8: =IF(F8="",MEDIAN(SalesTbl[Quantity]),F8) -> 2
A9: SALE7 | B9: 45248 | C9: CUST1152 | D9: PROD70 | E9: STORE8 | F9: 4 | G9: 342.39 | H9: 0.23 | I9: PayPal | J9: 1054.5612 | K9: =IF(J9="",MEDIAN(SalesTbl[Total_Amount]),J9) -> 1054.5612 | L9: =IF(H9="",MEDIAN(SalesTbl[Discount]),H9) -> 0.23 | M9: =IF(G9="",MEDIAN(SalesTbl[Unit_Price]),G9) -> 342.39 | N9: =IF(F9="",MEDIAN(SalesTbl[Quantity]),F9) -> 4
A10: SALE8 | B10: 45781 | C10: CUST1187 | D10: PROD99 | E10: STORE5 | G10: 448.25 | H10: 0.07 | I10: PayPal | J10: 1250.6175 | K10: =IF(J10="",MEDIAN(SalesTbl[Total_Amount]),J10) -> 1250.6175 | L10: =IF(H10="",MEDIAN(SalesTbl[Discount]),H10) -> 0.07 | M10: =IF(G10="",MEDIAN(SalesTbl[Unit_Price]),G10) -> 448.25 | N10: =IF(F10="",MEDIAN(SalesTbl[Quantity]),F10) -> 2
A11: SALE9 | B11: 45869 | C11: CUST1464 | D11: PROD33 | E11: STORE0 | F11: 2 | G11: 873.17 | H11: 0.23 | I11: PayPal | J11: 1344.6818 | K11: =IF(J11="",MEDIAN(SalesTbl[Total_Amount]),J11) -> 1344.6818 | L11: =IF(H11="",MEDIAN(SalesTbl[Discount]),H11) -> 0.23 | M11: =IF(G11="",MEDIAN(SalesTbl[Unit_Price]),G11) -> 873.17 | N11: =IF(F11="",MEDIAN(SalesTbl[Quantity]),F11) -> 2
A12: SALE10 | B12: 45335 | C12: CUST1065 | D12: PROD24 | E12: STORE14 | F12: 1 | G12: 278.63 | H12: 0.07 | I12: Credit Card | J12: 259.1259 | K12: =IF(J12="",MEDIAN(SalesTbl[Total_Amount]),J12) -> 259.1259 | L12: =IF(H12="",MEDIAN(SalesTbl[Discount]),H12) -> 0.07 | M12: =IF(G12="",MEDIAN(SalesTbl[Unit_Price]),G12) -> 278.63 | N12: =IF(F12="",MEDIAN(SalesTbl[Quantity]),F12) -> 1
A13: SALE11 | B13: 45801 | C13: CUST1320 | D13: PROD39 | E13: STORE1 | F13: 4 | G13: 286.92 | H13: 0.17 | I13: Credit Card | J13: 952.5744 | K13: =IF(J13="",MEDIAN(SalesTbl[Total_Amount]),J13) -> 952.5744 | L13: =IF(H13="",MEDIAN(SalesTbl[Discount]),H13) -> 0.17 | M13: =IF(G13="",MEDIAN(SalesTbl[Unit_Price]),G13) -> 286.92 | N13: =IF(F13="",MEDIAN(SalesTbl[Quantity]),F13) -> 4
A14: SALE12 | B14: 45528 | C14: CUST1237 | D14: PROD88 | E14: STORE4 | F14: 4 | G14: 644.58 | H14: 0.01 | I14: Credit Card | J14: 2552.5368 | K14: =IF(J14="",MEDIAN(SalesTbl[Total_Amount]),J14) -> 2552.5368 | L14: =IF(H14="",MEDIAN(SalesTbl[Discount]),H14) -> 0.01 | M14: =IF(G14="",MEDIAN(SalesTbl[Unit_Price]),G14) -> 644.58 | N14: =IF(F14="",MEDIAN(SalesTbl[Quantity]),F14) -> 4
A15: SALE13 | B15: 45875 | C15: CUST1443 | D15: PROD34 | E15: STORE16 | F15: 2 | G15: 316.9 | H15: 0.3 | I15: PayPal | J15: 443.66 | K15: =IF(J15="",MEDIAN(SalesTbl[Total_Amount]),J15) -> 443.66 | L15: =IF(H15="",MEDIAN(SalesTbl[Discount]),H15) -> 0.3 | M15: =IF(G15="",MEDIAN(SalesTbl[Unit_Price]),G15) -> 316.9 | N15: =IF(F15="",MEDIAN(SalesTbl[Quantity]),F15) -> 2
A16: SALE14 | B16: 45829 | C16: CUST1348 | D16: PROD24 | E16: STORE15 | F16: 4 | G16: 403.47 | H16: 0.29 | I16: PayPal | J16: 1145.8548 | K16: =IF(J16="",MEDIAN(SalesTbl[Total_Amount]),J16) -> 1145.8548 | L16: =IF(H16="",MEDIAN(SalesTbl[Discount]),H16) -> 0.29 | M16: =IF(G16="",MEDIAN(SalesTbl[Unit_Price]),G16) -> 403.47 | N16: =IF(F16="",MEDIAN(SalesTbl[Quantity]),F16) -> 4
A17: SALE15 | B17: 45636 | C17: CUST1435 | D17: PROD36 | E17: STORE9 | G17: 871.34 | H17: 0.04 | I17: COD | J17: 2509.4592 | K17: =IF(J17="",MEDIAN(SalesTbl[Total_Amount]),J17) -> 2509.4592 | L17: =IF(H17="",MEDIAN(SalesTbl[Discount]),H17) -> 0.04 | M17: =IF(G17="",MEDIAN(SalesTbl[Unit_Price]),G17) -> 871.34 | N17: =IF(F17="",MEDIAN(SalesTbl[Quantity]),F17) -> 2
A18: SALE16 | B18: 45913 | C18: CUST1276 | D18: PROD65 | E18: STORE19 | F18: 2 | G18: 451.98 | H18: 0.25 | I18: Credit Card | J18: 677.97 | K18: =IF(J18="",MEDIAN(SalesTbl[Total_Amount]),J18) -> 677.97 | L18: =IF(H18="",MEDIAN(SalesTbl[Discount]),H18) -> 0.25 | M18: =IF(G18="",MEDIAN(SalesTbl[Unit_Price]),G18) -> 451.98 | N18: =IF(F18="",MEDIAN(SalesTbl[Quantity]),F18) -> 2
A19: SALE17 | B19: 45637 | C19: CUST1079 | D19: PROD27 | E19: STORE4 | F19: 2 | G19: 502.69 | H19: 0.23 | I19: Credit Card | J19: 774.1426 | K19: =IF(J19="",MEDIAN(SalesTbl[Total_Amount]),J19) -> 774.1426 | L19: =IF(H19="",MEDIAN(SalesTbl[Discount]),H19) -> 0.23 | M19: =IF(G19="",MEDIAN(SalesTbl[Unit_Price]),G19) -> 502.69 | N19: =IF(F19="",MEDIAN(SalesTbl[Quantity]),F19) -> 2
A20: SALE18 | B20: 45517 | C20: CUST1094 | D20: PROD39 | E20: STORE4 | F20: 2 | G20: 559.23 | H20: 0.25 | I20: COD | J20: 838.845 | K20: =IF(J20="",MEDIAN(SalesTbl[Total_Amount]),J20) -> 838.845 | L20: =IF(H20="",MEDIAN(SalesTbl[Discount]),H20) -> 0.25 | M20: =IF(G20="",MEDIAN(SalesTbl[Unit_Price]),G20) -> 559.23 | N20: =IF(F20="",MEDIAN(SalesTbl[Quantity]),F20) -> 2
A21: SALE19 | B21: 45369 | C21: CUST1239 | D21: PROD60 | E21: STORE13 | F21: 4 | H21: 0.04 | I21: COD | J21: 1782.4512 | K21: =IF(J21="",MEDIAN(SalesTbl[Total_Amount]),J21) -> 1782.4512 | L21: =IF(H21="",MEDIAN(SalesTbl[Discount]),H21) -> 0.04 | M21: =IF(G21="",MEDIAN(SalesTbl[Unit_Price]),G21) -> 527.905 | N21: =IF(F21="",MEDIAN(SalesTbl[Quantity]),F21) -> 4
A22: SALE20 | B22: 45843 | C22: CUST1144 | D22: PROD72 | E22: STORE17 | F22: 3 | G22: 986.04 | H22: 0.27 | I22: COD | J22: 2159.4276 | K22: =IF(J22="",MEDIAN(SalesTbl[Total_Amount]),J22) -> 2159.4276 | L22: =IF(H22="",MEDIAN(SalesTbl[Discount]),H22) -> 0.27 | M22: =IF(G22="",MEDIAN(SalesTbl[Unit_Price]),G22) -> 986.04 | N22: =IF(F22="",MEDIAN(SalesTbl[Quantity]),F22) -> 3
A23: SALE21 | B23: 45447 | C23: CUST1396 | D23: PROD43 | E23: STORE18 | F23: 1 | G23: 589.56 | H23: 0.22 | I23: Credit Card | J23: 459.8568 | K23: =IF(J23="",MEDIAN(SalesTbl[Total_Amount]),J23) -> 459.8568 | L23: =IF(H23="",MEDIAN(SalesTbl[Discount]),H23) -> 0.22 | M23: =IF(G23="",MEDIAN(SalesTbl[Unit_Price]),G23) -> 589.56 | N23: =IF(F23="",MEDIAN(SalesTbl[Quantity]),F23) -> 1
A24: SALE22 | B24: 45394 | C24: CUST1476 | D24: PROD69 | E24: STORE10 | F24: 3 | G24: 979.42 | H24: 0.03 | I24: PayPal | J24: 2850.1122 | K24: =IF(J24="",MEDIAN(SalesTbl[Total_Amount]),J24) -> 2850.1122 | L24: =IF(H24="",MEDIAN(SalesTbl[Discount]),H24) -> 0.03 | M24: =IF(G24="",MEDIAN(SalesTbl[Unit_Price]),G24) -> 979.42 | N24: =IF(F24="",MEDIAN(SalesTbl[Quantity]),F24) -> 3
A25: SALE23 | B25: 45466 | C25: CUST1368 | D25: PROD12 | E25: STORE8 | F25: 1 | G25: 719.28 | H25: 0.08 | I25: Credit Card | J25: 661.7376 | K25: =IF(J25="",MEDIAN(SalesTbl[Total_Amount]),J25) -> 661.7376 | L25: =IF(H25="",MEDIAN(SalesTbl[Discount]),H25) -> 0.08 | M25: =IF(G25="",MEDIAN(SalesTbl[Unit_Price]),G25) -> 719.28 | N25: =IF(F25="",MEDIAN(SalesTbl[Quantity]),F25) -> 1
A26: SALE24 | B26: 45908 | C26: CUST1186 | D26: PROD67 | E26: STORE6 | F26: 3 | G26: 77.6 | H26: 0.07 | I26: Credit Card | J26: 216.504 | K26: =IF(J26="",MEDIAN(SalesTbl[Total_Amount]),J26) -> 216.504 | L26: =IF(H26="",MEDIAN(SalesTbl[Discount]),H26) -> 0.07 | M26: =IF(G26="",MEDIAN(SalesTbl[Unit_Price]),G26) -> 77.6 | N26: =IF(F26="",MEDIAN(SalesTbl[Quantity]),F26) -> 3
A27: SALE25 | B27: 45552 | C27: CUST1381 | D27: PROD5 | E27: STORE3 | F27: 4 | G27: 852.71 | H27: 0.14 | I27: PayPal | J27: 2933.3224 | K27: =IF(J27="",MEDIAN(SalesTbl[Total_Amount]),J27) -> 2933.3224 | L27: =IF(H27="",MEDIAN(SalesTbl[Discount]),H27) -> 0.14 | M27: =IF(G27="",MEDIAN(SalesTbl[Unit_Price]),G27) -> 852.71 | N27: =IF(F27="",MEDIAN(SalesTbl[Quantity]),F27) -> 4
A28: SALE26 | B28: 45294 | C28: CUST1213 | D28: PROD98 | E28: STORE8 | F28: 4 | G28: 156.16 | I28: Credit Card | J28: 599.6544 | K28: =IF(J28="",MEDIAN(SalesTbl[Total_Amount]),J28) -> 599.6544 | L28: =IF(H28="",MEDIAN(SalesTbl[Discount]),H28) -> 0.14 | M28: =IF(G28="",MEDIAN(SalesTbl[Unit_Price]),G28) -> 156.16 | N28: =IF(F28="",MEDIAN(SalesTbl[Quantity]),F28) -> 4
A29: SALE27 | B29: 45710 | C29: CUST1200 | D29: PROD77 | E29: STORE8 | F29: 3 | G29: 815.49 | H29: 0.17 | I29: Credit Card | J29: 2030.5701 | K29: =IF(J29="",MEDIAN(SalesTbl[Total_Amount]),J29) -> 2030.5701 | L29: =IF(H29="",MEDIAN(SalesTbl[Discount]),H29) -> 0.17 | M29: =IF(G29="",MEDIAN(SalesTbl[Unit_Price]),G29) -> 815.49 | N29: =IF(F29="",MEDIAN(SalesTbl[Quantity]),F29) -> 3
A30: SALE28 | B30: 45923 | C30: CUST1148 | D30: PROD13 | E30: STORE2 | F30: 2 | G30: 74.21 | H30: 0.11 | I30: PayPal | J30: 132.0938 | K30: =IF(J30="",MEDIAN(SalesTbl[Total_Amount]),J30) -> 132.0938 | L30: =IF(H30="",MEDIAN(SalesTbl[Discount]),H30) -> 0.11 | M30: =IF(G30="",MEDIAN(SalesTbl[Unit_Price]),G30) -> 74.21 | N30: =IF(F30="",MEDIAN(SalesTbl[Quantity]),F30) -> 2
A31: SALE29 | B31: 45302 | C31: CUST1348 | D31: PROD99 | E31: STORE3 | G31: 451.67 | H31: 0.15 | I31: Credit Card | J31: 1535.678 | K31: =IF(J31="",MEDIAN(SalesTbl[Total_Amount]),J31) -> 1535.678 | L31: =IF(H31="",MEDIAN(SalesTbl[Discount]),H31) -> 0.15 | M31: =IF(G31="",MEDIAN(SalesTbl[Unit_Price]),G31) -> 451.67 | N31: =IF(F31="",MEDIAN(SalesTbl[Quantity]),F31) -> 2
A32: SALE30 | B32: 45217 | C32: CUST1028 | D32: PROD5 | E32: STORE19 | F32: 1 | G32: 429.38 | H32: 0.13 | I32: PayPal | J32: 373.5606 | K32: =IF(J32="",MEDIAN(SalesTbl[Total_Amount]),J32) -> 373.5606 | L32: =IF(H32="",MEDIAN(SalesTbl[Discount]),H32) -> 0.13 | M32: =IF(G32="",MEDIAN(SalesTbl[Unit_Price]),G32) -> 429.38 | N32: =IF(F32="",MEDIAN(SalesTbl[Quantity]),F32) -> 1
A33: SALE31 | B33: 45593 | C33: CUST1412 | D33: PROD53 | E33: STORE12 | F33: 2 | G33: 148.96 | H33: 0.03 | I33: COD | J33: 288.9824 | K33: =IF(J33="",MEDIAN(SalesTbl[Total_Amount]),J33) -> 288.9824 | L33: =IF(H33="",MEDIAN(SalesTbl[Discount]),H33) -> 0.03 | M33: =IF(G33="",MEDIAN(SalesTbl[Unit_Price]),G33) -> 148.96 | N33: =IF(F33="",MEDIAN(SalesTbl[Quantity]),F33) -> 2
A34: SALE32 | B34: 45597 | C34: CUST1398 | D34: PROD75 | E34: STORE8 | F34: 4 | G34: 313.83 | H34: 0.08 | I34: Credit Card | J34: 1154.8944 | K34: =IF(J34="",MEDIAN(SalesTbl[Total_Amount]),J34) -> 1154.8944 | L34: =IF(H34="",MEDIAN(SalesTbl[Discount]),H34) -> 0.08 | M34: =IF(G34="",MEDIAN(SalesTbl[Unit_Price]),G34) -> 313.83 | N34: =IF(F34="",MEDIAN(SalesTbl[Quantity]),F34) -> 4
A35: SALE33 | B35: 45620 | C35: CUST1453 | D35: PROD12 | E35: STORE6 | F35: 2 | G35: 717.31 | H35: 0.15 | I35: Credit Card | J35: 1219.427 | K35: =IF(J35="",MEDIAN(SalesTbl[Total_Amount]),J35) -> 1219.427 | L35: =IF(H35="",MEDIAN(SalesTbl[Discount]),H35) -> 0.15 | M35: =IF(G35="",MEDIAN(SalesTbl[Unit_Price]),G35) -> 717.31 | N35: =IF(F35="",MEDIAN(SalesTbl[Quantity]),F35) -> 2
A36: SALE34 | B36: 45215 | C36: CUST1344 | D36: PROD79 | E36: STORE1 | G36: 873.22 | H36: 0.18 | I36: Credit Card | J36: 2148.1212 | K36: =IF(J36="",MEDIAN(SalesTbl[Total_Amount]),J36) -> 2148.1212 | L36: =IF(H36="",MEDIAN(SalesTbl[Discount]),H36) -> 0.18 | M36: =IF(G36="",MEDIAN(SalesTbl[Unit_Price]),G36) -> 873.22 | N36: =IF(F36="",MEDIAN(SalesTbl[Quantity]),F36) -> 2
A37: SALE35 | B37: 45878 | C37: CUST1218 | D37: PROD16 | E37: STORE3 | F37: 4 | G37: 109.36 | H37: 0.19 | I37: COD | J37: 354.3264 | K37: =IF(J37="",MEDIAN(SalesTbl[Total_Amount]),J37) -> 354.3264 | L37: =IF(H37="",MEDIAN(SalesTbl[Discount]),H37) -> 0.19 | M37: =IF(G37="",MEDIAN(SalesTbl[Unit_Price]),G37) -> 109.36 | N37: =IF(F37="",MEDIAN(SalesTbl[Quantity]),F37) -> 4
A38: SALE36 | B38: 45635 | C38: CUST1086 | D38: PROD5 | E38: STORE7 | F38: 3 | G38: 559.52 | H38: 0.16 | I38: PayPal | J38: 1409.9904 | K38: =IF(J38="",MEDIAN(SalesTbl[Total_Amount]),J38) -> 1409.9904 | L38: =IF(H38="",MEDIAN(SalesTbl[Discount]),H38) -> 0.16 | M38: =IF(G38="",MEDIAN(SalesTbl[Unit_Price]),G38) -> 559.52 | N38: =IF(F38="",MEDIAN(SalesTbl[Quantity]),F38) -> 3
A39: SALE37 | B39: 45329 | C39: CUST1492 | D39: PROD10 | E39: STORE17 | F39: 3 | G39: 121.76 | H39: 0.27 | I39: PayPal | J39: 266.6544 | K39: =IF(J39="",MEDIAN(SalesTbl[Total_Amount]),J39) -> 266.6544 | L39: =IF(H39="",MEDIAN(SalesTbl[Discount]),H39) -> 0.27 | M39: =IF(G39="",MEDIAN(SalesTbl[Unit_Price]),G39) -> 121.76 | N39: =IF(F39="",MEDIAN(SalesTbl[Quantity]),F39) -> 3
A40: SALE38 | B40: 45378 | C40: CUST1189 | D40: PROD33 | E40: STORE13 | F40: 4 | G40: 735.32 | H40: 0.06 | I40: COD | J40: 2764.8032 | K40: =IF(J40="",MEDIAN(SalesTbl[Total_Amount]),J40) -> 2764.8032 | L40: =IF(H40="",MEDIAN(SalesTbl[Discount]),H40) -> 0.06 | M40: =IF(G40="",MEDIAN(SalesTbl[Unit_Price]),G40) -> 735.32 | N40: =IF(F40="",MEDIAN(SalesTbl[Quantity]),F40) -> 4
...

Sheet Data_Analysis
A1: Sales_ID | B1: Order_Date | C1: Customer_ID | D1: Product_ID | E1: Product Name | F1: Cost of Product | G1: Store_ID | H1: Quantity | I1: Unit_Price | J1: Discount | K1: Payment_Type | L1: Total_Amount | M1: Gender | N1: Age | O1: Customer City | P1: Customer Level | Q1: Store City | R1: Store Region
A2: SALE0 | B2: 45480 | C2: CUST1409 | D2: PROD97 | E2: =VLOOKUP(D2,[2]Product_Dim!$A$2:$G$101,2,FALSE) -> Cricket Bat | F2: =VLOOKUP(D2,[2]Product_Dim!$A$2:$G$101,6,FALSE) -> 245.98 | G2: STORE3 | H2: 1 | I2: 218.04 | J2: 0.09 | K2: Credit Card | L2: 198.4164 | M2: =VLOOKUP(C2,'[2]Customer Detail'!$A$2:$H$501,4,FALSE) -> Male | N2: =VLOOKUP(C2,'[2]Customer Detail'!$A$2:$H$501,3,FALSE) -> 55 | O2: =VLOOKUP(C2,'[2]Customer Detail'!$A$2:$H$501,5,FALSE) -> Kathleenport | P2: =VLOOKUP(C2,'[2]Customer Detail'!$A$1:$H$501,8,FALSE) -> Gold | Q2: =VLOOKUP(G2,[2]Store_Dim!$A$1:$E$21,4,FALSE) -> Hoodberg | R2: =VLOOKUP(G2,[2]Store_Dim!$A$2:$E$21,3,FALSE) -> North
A3: SALE1 | B3: 45285 | C3: CUST1467 | D3: PROD74 | E3: =VLOOKUP(D3,[2]Product_Dim!$A$2:$G$101,2,FALSE) -> Bluetooth Car Audio System | F3: =VLOOKUP(D3,[2]Product_Dim!$A$2:$G$101,6,FALSE) -> 403.71 | G3: STORE17 | H3: 3 | I3: 104.47 | J3: 0.27 | K3: PayPal | L3: 228.7893 | M3: =VLOOKUP(C3,'[2]Customer Detail'!$A$2:$H$501,4,FALSE) -> Female | N3: =VLOOKUP(C3,'[2]Customer Detail'!$A$2:$H$501,3,FALSE) -> 63 | O3: =VLOOKUP(C3,'[2]Customer Detail'!$A$2:$H$501,5,FALSE) -> Oneillfurt | P3: =VLOOKUP(C3,'[2]Customer Detail'!$A$1:$H$501,8,FALSE) -> Gold | Q3: =VLOOKUP(G3,[2]Store_Dim!$A$1:$E$21,4,FALSE) -> Bensonhaven | R3: =VLOOKUP(G3,[2]Store_Dim!$A$2:$E$21,3,FALSE) -> North
A4: SALE2 | B4: 45357 | C4: CUST1056 | D4: PROD49 | E4: =VLOOKUP(D4,[2]Product_Dim!$A$2:$G$101,2,FALSE) -> Men's Roll-On Perfume | F4: =VLOOKUP(D4,[2]Product_Dim!$A$2:$G$101,6,FALSE) -> 43.29 | G4: STORE8 | H4: 4 | I4: 914.05 | J4: 0.25 | K4: Credit Card | L4: 2742.15 | M4: =VLOOKUP(C4,'[2]Customer Detail'!$A$2:$H$501,4,FALSE) -> Female | N4: =VLOOKUP(C4,'[2]Customer Detail'!$A$2:$H$501,3,FALSE) -> 49 | O4: =VLOOKUP(C4,'[2]Customer Detail'!$A$2:$H$501,5,FALSE) -> Deborahberg | P4: =VLOOKUP(C4,'[2]Customer Detail'!$A$1:$H$501,8,FALSE) -> Gold | Q4: =VLOOKUP(G4,[2]Store_Dim!$A$1:$E$21,4,FALSE) -> Thompsonborough | R4: =VLOOKUP(G4,[2]Store_Dim!$A$2:$E$21,3,FALSE) -> West
A5: SALE3 | B5: 45259 | C5: CUST1346 | D5: PROD76 | E5: =VLOOKUP(D5,[2]Product_Dim!$A$2:$G$101,2,FALSE) -> Wireless Mouse | F5: =VLOOKUP(D5,[2]Product_Dim!$A$2:$G$101,6,FALSE) -> 392.89 | G5: STORE8 | H5: 1 | I5: 921.51 | J5: 0.16 | K5: COD | L5: 774.0684 | M5: =VLOOKUP(C5,'[2]Customer Detail'!$A$2:$H$501,4,FALSE) -> Female | N5: =VLOOKUP(C5,'[2]Customer Detail'!$A$2:$H$501,3,FALSE) -> 58 | O5: =VLOOKUP(C5,'[2]Customer Detail'!$A$2:$H$501,5,FALSE) -> Port Crystalberg | P5: =VLOOKUP(C5,'[2]Customer Detail'!$A$1:$H$501,8,FALSE) -> Platinum | Q5: =VLOOKUP(G5,[2]Store_Dim!$A$1:$E$21,4,FALSE) -> Thompsonborough | R5: =VLOOKUP(G5,[2]Store_Dim!$A$2:$E$21,3,FALSE) -> West
A6: SALE4 | B6: 45444 | C6: CUST1493 | D6: PROD59 | E6: =VLOOKUP(D6,[2]Product_Dim!$A$2:$G$101,2,FALSE) -> Men's Hair Styling Gel | F6: =VLOOKUP(D6,[2]Product_Dim!$A$2:$G$101,6,FALSE) -> 17.31 | G6: STORE5 | H6: 3 | I6: 745.3 | J6: 0.18 | K6: Credit Card | L6: 1833.438 | M6: =VLOOKUP(C6,'[2]Customer Detail'!$A$2:$H$501,4,FALSE) -> Male | N6: =VLOOKUP(C6,'[2]Customer Detail'!$A$2:$H$501,3,FALSE) -> 28 | O6: =VLOOKUP(C6,'[2]Customer Detail'!$A$2:$H$501,5,FALSE) -> South William | P6: =VLOOKUP(C6,'[2]Customer Detail'!$A$1:$H$501,8,FALSE) -> Silver | Q6: =VLOOKUP(G6,[2]Store_Dim!$A$1:$E$21,4,FALSE) -> New Michaelchester | R6: =VLOOKUP(G6,[2]Store_Dim!$A$2:$E$21,3,FALSE) -> North
A7: SALE5 | B7: 45499 | C7: CUST1116 | D7: PROD15 | E7: =VLOOKUP(D7,[2]Product_Dim!$A$2:$G$101,2,FALSE) -> 4K Home Projector | F7: =VLOOKUP(D7,[2]Product_Dim!$A$2:$G$101,6,FALSE) -> 465.34 | G7: STORE7 | H7: 3 | I7: 147.01 | J7: 0.19 | K7: COD | L7: 357.2343 | M7: =VLOOKUP(C7,'[2]Customer Detail'!$A$2:$H$501,4,FALSE) -> Female | N7: =VLOOKUP(C7,'[2]Customer Detail'!$A$2:$H$501,3,FALSE) -> 18 | O7: =VLOOKUP(C7,'[2]Customer Detail'!$A$2:$H$501,5,FALSE) -> North Davidport | P7: =VLOOKUP(C7,'[2]Customer Detail'!$A$1:$H$501,8,FALSE) -> Platinum | Q7: =VLOOKUP(G7,[2]Store_Dim!$A$1:$E$21,4,FALSE) -> Williamsfurt | R7: =VLOOKUP(G7,[2]Store_Dim!$A$2:$E$21,3,FALSE) -> South
A8: SALE6 | B8: 45998 | C8: CUST1016 | D8: PROD56 | E8: =VLOOKUP(D8,[2]Product_Dim!$A$2:$G$101,2,FALSE) -> Premium Blanket Throw | F8: =VLOOKUP(D8,[2]Product_Dim!$A$2:$G$101,6,FALSE) -> 461.47 | G8: STORE4 | H8: 2 | I8: 785.31 | J8: 0.15 | K8: PayPal | L8: 1335.027 | M8: =VLOOKUP(C8,'[2]Customer Detail'!$A$2:$H$501,4,FALSE) -> Female | N8: =VLOOKUP(C8,'[2]Customer Detail'!$A$2:$H$501,3,FALSE) -> 24 | O8: =VLOOKUP(C8,'[2]Customer Detail'!$A$2:$H$501,5,FALSE) -> South Christopher | P8: =VLOOKUP(C8,'[2]Customer Detail'!$A$1:$H$501,8,FALSE) -> Bronze | Q8: =VLOOKUP(G8,[2]Store_Dim!$A$1:$E$21,4,FALSE) -> Port Sharon | R8: =VLOOKUP(G8,[2]Store_Dim!$A$2:$E$21,3,FALSE) -> South
A9: SALE7 | B9: 45248 | C9: CUST1152 | D9: PROD70 | E9: =VLOOKUP(D9,[2]Product_Dim!$A$2:$G$101,2,FALSE) -> Kitchen Storage Rack | F9: =VLOOKUP(D9,[2]Product_Dim!$A$2:$G$101,6,FALSE) -> 138.05 | G9: STORE8 | H9: 4 | I9: 342.39 | J9: 0.23 | K9: PayPal | L9: 1054.5612 | M9: =VLOOKUP(C9,'[2]Customer Detail'!$A$2:$H$501,4,FALSE) -> Female | N9: =VLOOKUP(C9,'[2]Customer Detail'!$A$2:$H$501,3,FALSE) -> 41 | O9: =VLOOKUP(C9,'[2]Customer Detail'!$A$2:$H$501,5,FALSE) -> Jaredville | P9: =VLOOKUP(C9,'[2]Customer Detail'!$A$1:$H$501,8,FALSE) -> Platinum | Q9: =VLOOKUP(G9,[2]Store_Dim!$A$1:$E$21,4,FALSE) -> Thompsonborough | R9: =VLOOKUP(G9,[2]Store_Dim!$A$2:$E$21,3,FALSE) -> West
A10: SALE8 | B10: 45752 | C10: CUST1187 | D10: PROD99 | E10: =VLOOKUP(D10,[2]Product_Dim!$A$2:$G$101,2,FALSE) -> Stainless Steel Cookware Set | F10: =VLOOKUP(D10,[2]Product_Dim!$A$2:$G$101,6,FALSE) -> 201.41 | G10: STORE5 | H10: 2.4802005 | I10: 448.25 | J10: 0.07 | K10: PayPal | L10: 1033.9274 | M10: =VLOOKUP(C10,'[3]Customer Detail'!$A$2:$H$501,4,FALSE) -> #N/A | N10: =VLOOKUP(C10,'[2]Customer Detail'!$A$2:$H$501,3,FALSE) -> 60 | O10: =VLOOKUP(C10,'[2]Customer Detail'!$A$2:$H$501,5,FALSE) -> Lake Blaketon | P10: =VLOOKUP(C10,'[2]Customer Detail'!$A$1:$H$501,8,FALSE) -> Platinum | Q10: =VLOOKUP(G10,[2]Store_Dim!$A$1:$E$21,4,FALSE) -> New Michaelchester | R10: =VLOOKUP(G10,[2]Store_Dim!$A$2:$E$21,3,FALSE) -> North
A11: SALE9 | B11: 45869 | C11: CUST1464 | D11: PROD33 | E11: =VLOOKUP(D11,[2]Product_Dim!$A$2:$G$101,2,FALSE) -> Modern Wall Clock | F11: =VLOOKUP(D11,[2]Product_Dim!$A$2:$G$101,6,FALSE) -> 179.77 | G11: STORE0 | H11: 2 | I11: 873.17 | J11: 0.23 | K11: PayPal | L11: 1344.6818 | M11: =VLOOKUP(C11,'[2]Customer Detail'!$A$2:$H$501,4,FALSE) -> Female | N11: =VLOOKUP(C11,'[2]Customer Detail'!$A$2:$H$501,3,FALSE) -> 45 | O11: =VLOOKUP(C11,'[2]Customer Detail'!$A$2:$H$501,5,FALSE) -> Grayland | P11: =VLOOKUP(C11,'[2]Customer Detail'!$A$1:$H$501,8,FALSE) -> Platinum | Q11: =VLOOKUP(G11,[2]Store_Dim!$A$1:$E$21,4,FALSE) -> Washingtonfurt | R11: =VLOOKUP(G11,[2]Store_Dim!$A$2:$E$21,3,FALSE) -> East
A12: SALE10 | B12: 45335 | C12: CUST1065 | D12: PROD24 | E12: =VLOOKUP(D12,[2]Product_Dim!$A$2:$G$101,2,FALSE) -> Foldable Camping Chair | F12: =VLOOKUP(D12,[2]Product_Dim!$A$2:$G$101,6,FALSE) -> 166.06 | G12: STORE14 | H12: 1 | I12: 278.63 | J12: 0.07 | K12: Credit Card | L12: 259.1259 | M12: =VLOOKUP(C12,'[2]Customer Detail'!$A$2:$H$501,4,FALSE) -> Female | N12: =VLOOKUP(C12,'[2]Customer Detail'!$A$2:$H$501,3,FALSE) -> 21 | O12: =VLOOKUP(C12,'[2]Customer Detail'!$A$2:$H$501,5,FALSE) -> Woodmouth | P12: =VLOOKUP(C12,'[2]Customer Detail'!$A$1:$H$501,8,FALSE) -> Silver | Q12: =VLOOKUP(G12,[2]Store_Dim!$A$1:$E$21,4,FALSE) -> Christopherland | R12: =VLOOKUP(G12,[2]Store_Dim!$A$2:$E$21,3,FALSE) -> South
A13: SALE11 | B13: 45801 | C13: CUST1320 | D13: PROD39 | E13: =VLOOKUP(D13,[2]Product_Dim!$A$2:$G$101,2,FALSE) -> Portable Power Bank | F13: =VLOOKUP(D13,[2]Product_Dim!$A$2:$G$101,6,FALSE) -> 326.06 | G13: STORE1 | H13: 4 | I13: 286.92 | J13: 0.17 | K13: Credit Card | L13: 952.5744 | M13: =VLOOKUP(C13,'[2]Customer Detail'!$A$2:$H$501,4,FALSE) -> Female | N13: =VLOOKUP(C13,'[2]Customer Detail'!$A$2:$H$501,3,FALSE) -> 34 | O13: =VLOOKUP(C13,'[2]Customer Detail'!$A$2:$H$501,5,FALSE) -> South Darrenland | P13: =VLOOKUP(C13,'[2]Customer Detail'!$A$1:$H$501,8,FALSE) -> Bronze | Q13: =VLOOKUP(G13,[2]Store_Dim!$A$1:$E$21,4,FALSE) -> Danielmouth | R13: =VLOOKUP(G13,[2]Store_Dim!$A$2:$E$21,3,FALSE) -> North
A14: SALE12 | B14: 45528 | C14: CUST1237 | D14: PROD88 | E14: =VLOOKUP(D14,[2]Product_Dim!$A$2:$G$101,2,FALSE) -> Sports Wrist Sweatbands | F14: =VLOOKUP(D14,[2]Product_Dim!$A$2:$G$101,6,FALSE) -> 131.24 | G14: STORE4 | H14: 4 | I14: 644.58 | J14: 0.01 | K14: Credit Card | L14: 2552.5368 | M14: =VLOOKUP(C14,'[2]Customer Detail'!$A$2:$H$501,4,FALSE) -> Female | N14: =VLOOKUP(C14,'[2]Customer Detail'!$A$2:$H$501,3,FALSE) -> 41 | O14: =VLOOKUP(C14,'[2]Customer Detail'!$A$2:$H$501,5,FALSE) -> Susanstad | P14: =VLOOKUP(C14,'[2]Customer Detail'!$A$1:$H$501,8,FALSE) -> Gold | Q14: =VLOOKUP(G14,[2]Store_Dim!$A$1:$E$21,4,FALSE) -> Port Sharon | R14: =VLOOKUP(G14,[2]Store_Dim!$A$2:$E$21,3,FALSE) -> South
A15: SALE13 | B15: 45816 | C15: CUST1443 | D15: PROD34 | E15: =VLOOKUP(D15,[2]Product_Dim!$A$2:$G$101,2,FALSE) -> Gaming Mechanical Keyboard | F15: =VLOOKUP(D15,[2]Product_Dim!$A$2:$G$101,6,FALSE) -> 419.28 | G15: STORE16 | H15: 2 | I15: 316.9 | J15: 0.3 | K15: PayPal | L15: 443.66 | M15: =VLOOKUP(C15,'[2]Customer Detail'!$A$2:$H$501,4,FALSE) -> Male | N15: =VLOOKUP(C15,'[2]Customer Detail'!$A$2:$H$501,3,FALSE) -> 51 | O15: =VLOOKUP(C15,'[2]Customer Detail'!$A$2:$H$501,5,FALSE) -> New Donnabury | P15: =VLOOKUP(C15,'[2]Customer Detail'!$A$1:$H$501,8,FALSE) -> Silver | Q15: =VLOOKUP(G15,[2]Store_Dim!$A$1:$E$21,4,FALSE) -> New Jimmymouth | R15: =VLOOKUP(G15,[2]Store_Dim!$A$2:$E$21,3,FALSE) -> West
A16: SALE14 | B16: 45829 | C16: CUST1348 | D16: PROD24 | E16: =VLOOKUP(D16,[2]Product_Dim!$A$2:$G$101,2,FALSE) -> Foldable Camping Chair | F16: =VLOOKUP(D16,[2]Product_Dim!$A$2:$G$101,6,FALSE) -> 166.06 | G16: STORE15 | H16: 4 | I16: 403.47 | J16: 0.29 | K16: PayPal | L16: 1145.8548 | M16: =VLOOKUP(C16,'[2]Customer Detail'!$A$2:$H$501,4,FALSE) -> Male | N16: =VLOOKUP(C16,'[2]Customer Detail'!$A$2:$H$501,3,FALSE) -> 55 | O16: =VLOOKUP(C16,'[2]Customer Detail'!$A$2:$H$501,5,FALSE) -> Shannonview | P16: =VLOOKUP(C16,'[2]Customer Detail'!$A$1:$H$501,8,FALSE) -> Silver | Q16: =VLOOKUP(G16,[2]Store_Dim!$A$1:$E$21,4,FALSE) -> East Jenniferstad | R16: =VLOOKUP(G16,[2]Store_Dim!$A$2:$E$21,3,FALSE) -> North
A17: SALE15 | B17: 45577 | C17: CUST1435 | D17: PROD36 | E17: =VLOOKUP(D17,[2]Product_Dim!$A$2:$G$101,2,FALSE) -> Women's Summer Dress | F17: =VLOOKUP(D17,[2]Product_Dim!$A$2:$G$101,6,FALSE) -> 223.43 | G17: STORE9 | H17: 2.4802005 | I17: 871.34 | J17: 0.04 | K17: COD | L17: 2074.654 | M17: =VLOOKUP(C17,'[2]Customer Detail'!$A$2:$H$501,4,FALSE) -> Female | N17: =VLOOKUP(C17,'[2]Customer Detail'!$A$2:$H$501,3,FALSE) -> 37 | O17: =VLOOKUP(C17,'[2]Customer Detail'!$A$2:$H$501,5,FALSE) -> Wesleyhaven | P17: =VLOOKUP(C17,'[2]Customer Detail'!$A$1:$H$501,8,FALSE) -> Silver | Q17: =VLOOKUP(G17,[2]Store_Dim!$A$1:$E$21,4,FALSE) -> East Johnstad | R17: =VLOOKUP(G17,[2]Store_Dim!$A$2:$E$21,3,FALSE) -> South
A18: SALE16 | B18: 45913 | C18: CUST1276 | D18: PROD65 | E18: =VLOOKUP(D18,[2]Product_Dim!$A$2:$G$101,2,FALSE) -> Adjustable Dumbbells 20kg | F18: =VLOOKUP(D18,[2]Product_Dim!$A$2:$G$101,6,FALSE) -> 240.63 | G18: STORE19 | H18: 2 | I18: 451.98 | J18: 0.25 | K18: Credit Card | L18: 677.97 | M18: =VLOOKUP(C18,'[2]Customer Detail'!$A$2:$H$501,4,FALSE) -> Male | N18: =VLOOKUP(C18,'[2]Customer Detail'!$A$2:$H$501,3,FALSE) -> 38 | O18: =VLOOKUP(C18,'[2]Customer Detail'!$A$2:$H$501,5,FALSE) -> Ericshire | P18: =VLOOKUP(C18,'[2]Customer Detail'!$A$1:$H$501,8,FALSE) -> Gold | Q18: =VLOOKUP(G18,[2]Store_Dim!$A$1:$E$21,4,FALSE) -> Vasquezborough | R18: =VLOOKUP(G18,[2]Store_Dim!$A$2:$E$21,3,FALSE) -> East
A19: SALE17 | B19: 45608 | C19: CUST1079 | D19: PROD27 | E19: =VLOOKUP(D19,[2]Product_Dim!$A$2:$G$101,2,FALSE) -> Decorative Floor Vase | F19: =VLOOKUP(D19,[2]Product_Dim!$A$2:$G$101,6,FALSE) -> 254.04362 | G19: STORE4 | H19: 2 | I19: 502.69 | J19: 0.23 | K19: Credit Card | L19: 774.1426 | M19: =VLOOKUP(C19,'[2]Customer Detail'!$A$2:$H$501,4,FALSE) -> Female | N19: =VLOOKUP(C19,'[2]Customer Detail'!$A$2:$H$501,3,FALSE) -> 22 | O19: =VLOOKUP(C19,'[2]Customer Detail'!$A$2:$H$501,5,FALSE) -> Nicoleborough | P19: =VLOOKUP(C19,'[2]Customer Detail'!$A$1:$H$501,8,FALSE) -> Platinum | Q19: =VLOOKUP(G19,[2]Store_Dim!$A$1:$E$21,4,FALSE) -> Port Sharon | R19: =VLOOKUP(G19,[2]Store_Dim!$A$2:$E$21,3,FALSE) -> South
A20: SALE18 | B20: 45517 | C20: CUST1094 | D20: PROD39 | E20: =VLOOKUP(D20,[2]Product_Dim!$A$2:$G$101,2,FALSE) -> Portable Power Bank | F20: =VLOOKUP(D20,[2]Product_Dim!$A$2:$G$101,6,FALSE) -> 326.06 | G20: STORE4 | H20: 2 | I20: 559.23 | J20: 0.25 | K20: COD | L20: 838.845 | M20: =VLOOKUP(C20,'[2]Customer Detail'!$A$2:$H$501,4,FALSE) -> Female | N20: =VLOOKUP(C20,'[2]Customer Detail'!$A$2:$H$501,3,FALSE) -> 43 | O20: =VLOOKUP(C20,'[2]Customer Detail'!$A$2:$H$501,5,FALSE) -> New Amyport | P20: =VLOOKUP(C20,'[2]Customer Detail'!$A$1:$H$501,8,FALSE) -> Gold | Q20: =VLOOKUP(G20,[2]Store_Dim!$A$1:$E$21,4,FALSE) -> Port Sharon | R20: =VLOOKUP(G20,[2]Store_Dim!$A$2:$E$21,3,FALSE) -> South
A21: SALE19 | B21: 45369 | C21: CUST1239 | D21: PROD60 | E21: =VLOOKUP(D21,[2]Product_Dim!$A$2:$G$101,2,FALSE) -> Luxury Perfume Spray | F21: =VLOOKUP(D21,[2]Product_Dim!$A$2:$G$101,6,FALSE) -> 482.75 | G21: STORE13 | H21: 4 | I21: 513.98477 | J21: 0.04 | K21: COD | L21: 1973.7015 | M21: =VLOOKUP(C21,'[2]Customer Detail'!$A$2:$H$501,4,FALSE) -> Female | N21: =VLOOKUP(C21,'[2]Customer Detail'!$A$2:$H$501,3,FALSE) -> 58 | O21: =VLOOKUP(C21,'[2]Customer Detail'!$A$2:$H$501,5,FALSE) -> Zamoraborough | P21: =VLOOKUP(C21,'[2]Customer Detail'!$A$1:$H$501,8,FALSE) -> Platinum | Q21: =VLOOKUP(G21,[2]Store_Dim!$A$1:$E$21,4,FALSE) -> Johnsonville | R21: =VLOOKUP(G21,[2]Store_Dim!$A$2:$E$21,3,FALSE) -> East
